[
    {
        "patch": "@Override\npublic void close() throws IOException {\n    try (InputStream in = this.input; OutputStream out = this.output) {\n        // no need to explicitly call close() on input and output\n    }\n}",
        "patched_method_loc": [
            96,
            102
        ],
        "status": "[CE]",
        "error_message": [
            "/external_disk/coding_space/ChatRepairRegression/experiments/tmp-prompt-bic/RegressionBug-24/BUGGY/src/main/java/org/cactoos/io/TeeInputStream.java: warnings found and -Werror specified"
        ],
        "validation_time": 3.3912270069122314,
        "response": "The bug-inducing commit message states that a branch named '__rultor' was merged. This suggests that changes from this branch might have introduced the bug in the `close()` method.\n\nConsidering the failing test case `org.cactoos.io.TeeInputStreamTest#leftInputUnclosed` with the error message `java.lang.AssertionError: Expected : <false>`, it seems that the issue is related to the input stream not being closed properly.\n\nTo fix this bug, we need to ensure that both `input` and `output` streams are closed properly, even if an exception occurs while closing one of them. One way to achieve this is by using try-with-resources to automatically close the streams. Here is the corrected version of the `close()` method:\n\n```java\n@Override\npublic void close() throws IOException {\n    try (InputStream in = this.input; OutputStream out = this.output) {\n        // no need to explicitly call close() on input and output\n    }\n}\n```\n\nBy using try-with-resources, the streams will be closed automatically when the try block exits, ensuring that they are properly closed even in the case of exceptions.",
        "input_tokens": 172,
        "output_tokens": 234,
        "total_cost": 0.00064
    },
    {
        "patch": "@Override\npublic void close() throws IOException {\n    try {\n        if (this.input != null) {\n            this.input.close();\n        }\n    } finally {\n        if (this.output != null) {\n            this.output.close();\n        }\n    }\n}",
        "patched_method_loc": [
            96,
            108
        ],
        "status": "[FE]",
        "error_message": [
            "org.cactoos.io.LoggingInputTest#logIntoCreatedLogger: java.lang.AssertionError: Expected : a string containing \"Read 8 byte(s)\"",
            "org.cactoos.io.TeeInputStreamTest#leftInputUnclosed: java.lang.AssertionError: Expected : <false>"
        ],
        "validation_time": 43.63523864746094,
        "response": "Based on the bug-inducing commit message \"Merge branch '__rultor'\", it seems like the bug was introduced during a merge operation from another branch, possibly introducing changes that caused the issue.\n\nGiven the failing test case \"org.cactoos.io.TeeInputStreamTest#leftInputUnclosed: java.lang.AssertionError: Expected : <false>\", it appears that the issue is related to the input stream not being properly closed.\n\nTo fix the bug, we need to ensure that both the input and output streams are properly closed in the `close()` method. Here is the corrected function:\n\n```java\n@Override\npublic void close() throws IOException {\n    try {\n        if (this.input != null) {\n            this.input.close();\n        }\n    } finally {\n        if (this.output != null) {\n            this.output.close();\n        }\n    }\n}\n```\n\nThis corrected function properly closes both the input and output streams, handling potential IOExceptions that may occur during the closing process.",
        "input_tokens": 172,
        "output_tokens": 200,
        "total_cost": 0.000572
    },
    {
        "patch": "@Override\npublic void close() throws IOException {\n    if (this.input != null) {\n        this.input.close();\n    }\n    if (this.output != null) {\n        this.output.close();\n    }\n}",
        "patched_method_loc": [
            96,
            105
        ],
        "status": "[FE]",
        "error_message": [
            "org.cactoos.io.TeeInputStreamTest#leftInputUnclosed: java.lang.AssertionError: Expected : <false>"
        ],
        "validation_time": 44.69077968597412,
        "response": "The bug-inducing commit message indicates that a merge was done from the branch '__rultor'. This merge likely introduced changes that led to the bug in the `close()` method. \n\nConsidering the failing test case `org.cactoos.io.TeeInputStreamTest#leftInputUnclosed` with the error message `java.lang.AssertionError: Expected : <false>`, it seems that the issue lies with the `close()` method not properly closing the input stream.\n\nTo fix this bug, we should ensure that both the input stream and output stream are closed individually and handle any potential exceptions that may occur. Here's the corrected `close()` method:\n\n```java\n@Override\npublic void close() throws IOException {\n    if (this.input != null) {\n        this.input.close();\n    }\n    if (this.output != null) {\n        this.output.close();\n    }\n}\n```\n\nThis updated version of the `close()` method checks if the input and output streams are not null before attempting to close them, thus avoiding potential `NullPointerException` issues.",
        "input_tokens": 172,
        "output_tokens": 213,
        "total_cost": 0.000598
    },
    {
        "patch": "@Override\npublic void close() throws IOException {\n    try (InputStream in = this.input; OutputStream out = this.output) {\n        // No need to explicitly call close here, as try-with-resources will handle it\n    }\n}",
        "patched_method_loc": [
            96,
            102
        ],
        "status": "[CE]",
        "error_message": [
            "/external_disk/coding_space/ChatRepairRegression/experiments/tmp-prompt-bic/RegressionBug-24/BUGGY/src/main/java/org/cactoos/io/TeeInputStream.java: warnings found and -Werror specified"
        ],
        "validation_time": 3.391857624053955,
        "response": "The bug is likely caused by the bug-inducing commit merging changes from the `__rultor` branch. The error message `org.cactoos.io.TeeInputStreamTest#leftInputUnclosed: java.lang.AssertionError: Expected : <false>` indicates that the `leftInputUnclosed` test failed because it expected the input stream to be closed (`false`), but it was not closed.\n\nTo fix this issue, we need to ensure that both `this.input` and `this.output` streams are closed properly in the `close` method. One common practice is to use try-with-resources to automatically close the streams even if an exception occurs.\n\nHere is the corrected version of the `close` method:\n\n```java\n@Override\npublic void close() throws IOException {\n    try (InputStream in = this.input; OutputStream out = this.output) {\n        // No need to explicitly call close here, as try-with-resources will handle it\n    }\n}\n```\n\nBy using try-with-resources, we ensure that both `this.input` and `this.output` streams are closed properly, which should resolve the issue reported in the failing test case.",
        "input_tokens": 172,
        "output_tokens": 234,
        "total_cost": 0.00064
    },
    {
        "patch": "@Override\npublic void close() throws IOException {\n    try (InputStream inputStream = this.input; OutputStream outputStream = this.output) {\n        // No need to manually close the streams here\n    }\n}",
        "patched_method_loc": [
            96,
            102
        ],
        "status": "[CE]",
        "error_message": [
            "/external_disk/coding_space/ChatRepairRegression/experiments/tmp-prompt-bic/RegressionBug-24/BUGGY/src/main/java/org/cactoos/io/TeeInputStream.java: warnings found and -Werror specified"
        ],
        "validation_time": 3.4582972526550293,
        "response": "Based on the bug-inducing commit message \"Merge branch '__rultor'\" and the failing test case error message \"org.cactoos.io.TeeInputStreamTest#leftInputUnclosed: java.lang.AssertionError: Expected : <false>\", it seems like the bug was introduced during a merge operation.\n\nThe failing test case \"leftInputUnclosed\" indicates that the left input stream was expected to be closed but it wasn't. This suggests that the bug in the `close()` method is related to not properly closing the input stream.\n\nTo fix the bug, we need to ensure that both the input and output streams are closed properly. We can do this by using try-with-resources to automatically close the streams when they are no longer needed.\n\nHere is the corrected `close()` method:\n\n```java\n@Override\npublic void close() throws IOException {\n    try (InputStream inputStream = this.input; OutputStream outputStream = this.output) {\n        // No need to manually close the streams here\n    }\n}\n```\n\nBy using try-with-resources, we ensure that both the input and output streams are properly closed even if an exception occurs during the closing process. This should fix the bug related to not closing the input stream.",
        "input_tokens": 172,
        "output_tokens": 245,
        "total_cost": 0.0006619999999999999
    },
    {
        "patch": "@Override\npublic void close() throws IOException {\n    try {\n        if (this.input != null) {\n            this.input.close();\n        }\n    } finally {\n        if (this.output != null) {\n            this.output.close();\n        }\n    }\n}",
        "patched_method_loc": [
            96,
            108
        ],
        "status": "[FE]",
        "error_message": [
            "org.cactoos.io.TeeInputStreamTest#leftInputUnclosed: java.lang.AssertionError: Expected : <false>"
        ],
        "validation_time": 43.228013038635254,
        "response": "Based on the bug-inducing commit message \"Merge branch '__rultor'\", it seems that the bug was introduced during a merge operation. The merge operation may have introduced changes that impacted the behavior of the function `close()`.\n\nGiven the failing test case `org.cactoos.io.TeeInputStreamTest#leftInputUnclosed`, which expects the left input to be closed, the issue likely lies in the handling of closing the input stream in the `close()` method.\n\nTo fix this bug, we should ensure that both the input and output streams are closed properly, even if an exception is thrown during the closing process. One way to achieve this is by using try-with-resources to automatically close the streams:\n\n```java\n@Override\npublic void close() throws IOException {\n    try {\n        if (this.input != null) {\n            this.input.close();\n        }\n    } finally {\n        if (this.output != null) {\n            this.output.close();\n        }\n    }\n}\n```\n\nThis revised implementation ensures that both the input and output streams are closed, handling any potential exceptions that may occur during the closing process.",
        "input_tokens": 172,
        "output_tokens": 225,
        "total_cost": 0.000622
    },
    {
        "patch": "@Override\npublic void close() throws IOException {\n    try {\n        if (this.input != null) {\n            this.input.close();\n        }\n    } finally {\n        if (this.output != null) {\n            this.output.close();\n        }\n    }\n}",
        "patched_method_loc": [
            96,
            108
        ],
        "status": "[FE]",
        "error_message": [
            "org.cactoos.io.TeeInputStreamTest#leftInputUnclosed: java.lang.AssertionError: Expected : <false>"
        ],
        "validation_time": 43.71486520767212,
        "response": "### Root Cause Analysis:\n\n1. The bug-inducing commit message mentions merging the branch '__rultor'.\n2. The failing test case 'org.cactoos.io.TeeInputStreamTest#leftInputUnclosed' reports an error related to an unclosed input stream.\n\n### Analysis and Solution:\n1. The bug-inducing commit message indicates a merge operation, which might have introduced changes that led to the issue.\n2. The failing test case error 'leftInputUnclosed' suggests that one of the input streams is left unclosed after the operation.\n\n### Corrected Function:\nConsidering the failing test case error related to an unclosed input stream, the corrected `close` method should ensure that both the input and output streams are properly closed. Here is the updated function:\n\n```java\n@Override\npublic void close() throws IOException {\n    try {\n        if (this.input != null) {\n            this.input.close();\n        }\n    } finally {\n        if (this.output != null) {\n            this.output.close();\n        }\n    }\n}\n```\n\n### Explanation:\n1. The corrected function checks if the input stream is not null before closing it to avoid a NullPointerException.\n2. The `try-finally` block ensures that even if an exception occurs during the closing of the input stream, the output stream is still closed.\n3. This approach ensures that both the input and output streams are closed properly, addressing the issue of the unclosed input stream reported in the failing test case.",
        "input_tokens": 172,
        "output_tokens": 300,
        "total_cost": 0.0007719999999999999
    },
    {
        "patch": "@Override\npublic void close() throws IOException {\n    try (InputStream in = this.input) {\n        // No need to explicitly close the input stream here, it will be closed automatically\n    }\n    // Close the output stream\n    this.output.close();\n}",
        "patched_method_loc": [
            96,
            104
        ],
        "status": "[CE]",
        "error_message": [
            "/external_disk/coding_space/ChatRepairRegression/experiments/tmp-prompt-bic/RegressionBug-24/BUGGY/src/main/java/org/cactoos/io/TeeInputStream.java: warnings found and -Werror specified"
        ],
        "validation_time": 3.443770170211792,
        "response": "The bug-inducing commit message indicates that a branch named '__rultor' was merged into the codebase. The error message related to the failing test case 'org.cactoos.io.TeeInputStreamTest#leftInputUnclosed' indicates that the left input stream is expected to be closed, but it is not closed.\n\nBased on the error message and the bug-inducing commit message, we can infer that the bug is related to the left input stream not being closed properly. Since the bug-inducing commit is a merge commit, it is likely that changes from the '__rultor' branch introduced this bug.\n\nTo fix the bug, we need to make sure that the left input stream is closed properly. We can achieve this by using a try-with-resources block to ensure that the input stream is closed even if an exception occurs:\n\n```java\n@Override\npublic void close() throws IOException {\n    try (InputStream in = this.input) {\n        // No need to explicitly close the input stream here, it will be closed automatically\n    }\n    // Close the output stream\n    this.output.close();\n}\n```\n\nBy using try-with-resources, we ensure that the input stream is closed properly, addressing the bug related to the left input stream not being closed.",
        "input_tokens": 172,
        "output_tokens": 256,
        "total_cost": 0.0006839999999999999
    },
    {
        "patch": "@Override\npublic void close() throws IOException {\n    try {\n        if (this.input != null) {\n            this.input.close();\n        }\n    } finally {\n        if (this.output != null) {\n            this.output.close();\n        }\n    }\n}",
        "patched_method_loc": [
            96,
            108
        ],
        "status": "[FE]",
        "error_message": [
            "org.cactoos.io.TeeInputStreamTest#leftInputUnclosed: java.lang.AssertionError: Expected : <false>"
        ],
        "validation_time": 42.99860882759094,
        "response": "The bug-inducing commit message indicates that a branch named '__rultor' was merged into the codebase. The error message mentions that the test case `org.cactoos.io.TeeInputStreamTest#leftInputUnclosed` failed with the assertion error `Expected: <false>`. This suggests that the input stream is not being properly closed in the `close()` method of the class.\n\nGiven that the `close()` method is supposed to close input and output streams, the bug seems to be related to the input stream not being closed correctly. To fix this issue, we should ensure that both the input and output streams are closed properly in the `close()` method.\n\nHere is the corrected version of the `close()` method:\n\n```java\n@Override\npublic void close() throws IOException {\n    try {\n        if (this.input != null) {\n            this.input.close();\n        }\n    } finally {\n        if (this.output != null) {\n            this.output.close();\n        }\n    }\n}\n```\n\nThis corrected version ensures that both the input and output streams are properly closed in a `try-finally` block to handle any potential exceptions that may occur during the closing process.",
        "input_tokens": 172,
        "output_tokens": 240,
        "total_cost": 0.000652
    },
    {
        "patch": "@Override\npublic void close() throws IOException {\n    try {\n        this.input.close();\n    } finally {\n        this.output.close();\n    }\n}",
        "patched_method_loc": [
            96,
            104
        ],
        "status": "[FE]",
        "error_message": [
            "org.cactoos.io.TeeInputStreamTest#leftInputUnclosed: java.lang.AssertionError: Expected : <false>"
        ],
        "validation_time": 43.16340970993042,
        "response": "### Root Cause Analysis:\n\n1. **Bug-Inducing Commit Message:** The bug-inducing commit message indicates that a branch named `__rultor` was merged into the codebase.\n   \n2. **Failing Test Case Error:** The failing test case `org.cactoos.io.TeeInputStreamTest#leftInputUnclosed` is reporting an `AssertionError` with the message \"Expected: <false>\". This suggests that the test is checking whether a resource (input stream) is left unclosed.\n\n3. **Analysis:** Considering the failing test case and the bug-inducing commit message, it is likely that the bug was introduced due to changes made in the `__rultor` branch that led to not properly closing a resource (input stream).\n\n### Corrected Function:\n\n```java\n@Override\npublic void close() throws IOException {\n    try {\n        this.input.close();\n    } finally {\n        this.output.close();\n    }\n}\n```\n\n### Explanation:\n- In the corrected function, I have added a try-finally block to ensure that both `this.input` and `this.output` are closed properly.\n- The `try` block attempts to close `this.input`.\n- The `finally` block ensures that `this.output` is closed even if an exception occurs while closing `this.input`.\n- This approach guarantees that both resources are closed correctly, addressing the issue identified in the failing test case and the bug-inducing commit.",
        "input_tokens": 172,
        "output_tokens": 294,
        "total_cost": 0.0007599999999999999
    }
]